data/replay_0923.json
{
  "strike_min": 5439.25,
  "strike_max": 5540.5,
  "num_lanes": 24,
  "frames": [
    {
      "frame_index": 0,
      "timestamp": "2025-04-14T09:23:00.079099-04:00",
      "life_progress": 0.0,
      "liquidity_density_factor": 0.429066,
      "gamma_metabolism_factor": 0.957472,
      "manipulation_factor": 0.0,
      "price_kinetic_factor": 0.0,
      "health_score": 0.627118,
      "health_state": "stressed",
      "ask_flow": [
        0.0,
        0.0,
        0.0,
        0.0,
        0.0,
        0.0,
        0.0,
        0.0,
        0.0,
        0.0,
        0.0,
        0.004115,
        0.211523,
        0.30535,
        0.264198,
        0.077366,
        1.0,
        0.176955,
        0.142387,
        0.232099,
        0.265844,
        0.11358,
        0.093004,
        0.009877
      ],
      "bid_flow": [
        0.065844,
        0.112757,
        0.081481,
        0.004115,
        0.03786,
        0.009053,
        0.040329,
        0.20823,
        0.139918,
        0.04856,
        0.095473,
        0.063374,
        0.0,
        0.0,
        0.0,
        0.0,
        0.0,
        0.0,
        0.0,
        0.0,
        0.0,
        0.0,
        0.0,
        0.0
      ],
      "side_imbalance": 0.523047,
      "order_density": 0.133333,
      "source_rows": 400,
      "organism_clock": "2025-04-14T09:23:00.079099-04:00"
    },
    {
      "frame_index": 1,
      "timestamp": "2025-04-14T09:23:01.041495-04:00",
      "life_progress": 0.002247,
      "liquidity_density_factor": 0.422145,
      "gamma_metabolism_factor": 0.958323,
      "manipulation_factor": 0.001081,
      "price_kinetic_factor": 0.0,
      "health_score": 0.625447,
      "health_state": "stressed",
      "ask_flow": [
        0.0,
        0.0,
        0.0,
        0.0,
        0.0,
        0.0,
        0.0,
        0.0,
        0.0,
        0.0,
        0.0,
        0.002469,
        0.211523,
        0.30535,
        0.264198,
        0.077366,
        1.0,
        0.176955,
        0.142387,
        0.232099,
        0.265844,
        0.11358,
        0.093004,
        0.009877
      ],
      "bid_flow": [
        0.065844,
        0.112757,
        0.081481,
        0.004115,
        0.03786,
        0.009053,
        0.040329,
        0.20823,
        0.139918,
        0.04856,
        0.095473,
        0.063374,
        0.0,
        0.0,
        0.0,
        0.0,
        0.0,
        0.0,
        0.0,
        0.0,
        0.0,
        0.0,
        0.0,
        0.0
      ],
      "side_imbalance": 0.52284,
      "order_density": 0.133333,
      "source_rows": 400,
      "organism_clock": "2025-04-14T09:23:00.213540-04:00"
    },
    {
      "frame_index": 2,
      "timestamp": "2025-04-14T09:23:01.059448-04:00",
      "life_progress": 0.004494,
      "liquidity_density_factor": 0.422145,
      "gamma_metabolism_factor": 0.958323,
      "manipulation_factor": 0.001081,
      "price_kinetic_factor": 0.0,
      "health_score": 0.625447,
      "health_state": "stressed",
      "ask_flow": [
        0.0,
        0.0,
        0.0,
        0.0,
        0.0,
        0.0,
        0.0,
        0.0,
        0.0,
        0.0,
        0.0,
        0.002469,
        0.211523,
        0.30535,
        0.264198,
        0.077366,
        1.0,
        0.176955,
        0.142387,
        0.232099,
        0.265844,
        0.11358,
        0.093004,
        0.009877
      ],
      "bid_flow": [
        0.065844,
        0.112757,
        0.081481,
        0.004115,
        0.03786,
        0.009053,
        0.040329,
        0.20823,
        0.139918,
        0.04856,
        0.095473,
        0.063374,
        0.0,
        0.0,
        0.0,
        0.0,
        0.0,
        0.0,
        0.0,
        0.0,
        0.0,
        0.0,
        0.0,
        0.0
      ],
      "side_imbalance": 0.52284,
      "order_density": 0.133333,
      "source_rows": 400,
      "organism_clock": "2025-04-14T09:23:00.347980-04:00"
    },
    {
      "frame_index": 3,
      "timestamp": "2025-04-14T09:23:01.081389-04:00",
      "life_progress": 0.006742,
      "liquidity_density_factor": 0.422145,
      "gamma_metabolism_factor": 0.958323,
      "manipulation_factor": 0.004324,
      "price_kinetic_factor": 0.0,
      "health_score": 0.624311,
      "health_state": "stressed",
      "ask_flow": [
        0.0,
        0.0,
        0.0,
        0.0,
        0.0,
        0.0,
        0.0,
        0.0,
        0.0,
        0.0,
        0.0,
        0.0,
        0.211523,
        0.30535,
        0.264198,
        0.077366,
        1.0,
        0.176955,
        0.142387,
        0.232099,
        0.265844,
        0.11358,
        0.093004,
        0.009877
      ],
      "bid_flow": [
        0.065844,
        0.112757,
        0.081481,
        0.004115,
        0.03786,
        0.009053,
        0.040329,
        0.20823,
        0.139918,
        0.04856,
        0.095473,
        0.065844,
        0.0,
        0.0,
        0.0,
        0.0,
        0.0,
        0.0,
        0.0,
        0.0,
        0.0,
        0.0,
        0.0,
        0.0
      ],
      "side_imbalance": 0.521541,
      "order_density": 0.133333,
      "source_rows": 400,
      "organism_clock": "2025-04-14T09:23:00.482481-04:00"
    },
    {
      "frame_index": 4,
      "timestamp": "2025-04-14T09:23:01.243715-04:00",
      "life_progress": 0.008989,
      "liquidity_density_factor": 0.422145,
      "gamma_metabolism_factor": 0.958323,
      "manipulation_factor": 0.004324,
      "price_kinetic_factor": 0.0,
      "health_score": 0.624311,
      "health_state": "stressed",
      "ask_flow": [
        0.0,
        0.0,
        0.0,
        0.0,
        0.0,
        0.0,
        0.0,
        0.0,
        0.0,
        0.0,
        0.0,
        0.0,
        0.211523,
        0.30535,
        0.264198,
        0.077366,
        1.0,
        0.176955,
        0.142387,
        0.232099,
        0.265844,
        0.11358,
        0.093004,
        0.009877
      ],
      "bid_flow": [
        0.065844,
        0.112757,
        0.081481,
        0.004115,
        0.03786,
        0.009053,
        0.040329,
        0.20823,
        0.139918,
        0.04856,
        0.095473,
        0.065844,
        0.0,
        0.0,
        0.0,
        0.0,
        0.0,
        0.0,
        0.0,
        0.0,
        0.0,
        0.0,
        0.0,
        0.0
      ],
      "side_imbalance": 0.521541,
      "order_density": 0.133333,
      "source_rows": 400,
      "organism_clock": "2025-04-14T09:23:00.616921-04:00"
    },
    {
      "frame_index": 5,
      "timestamp": "2025-04-14T09:23:01.345442-04:00",
      "life_progress": 0.011236,
      "liquidity_density_factor": 0.422145,
      "gamma_metabolism_factor": 0.958323,
      "manipulation_factor": 0.004324,
      "price_kinetic_factor": 0.0,
      "health_score": 0.624311,
      "health_state": "stressed",
      "ask_flow": [
        0.0,
        0.0,
        0.0,
        0.0,
        0.0,
        0.0,
        0.0,
        0.0,
        0.0,
        0.0,
        0.0,
        0.0,
        0.211523,
        0.30535,
        0.264198,
        0.077366,
        1.0,
        0.176955,
        0.142387,
        0.232099,
        0.265844,
        0.11358,
        0.093004,
        0.009877
      ],
      "bid_flow": [
        0.065844,
        0.112757,
        0.081481,
        0.004115,
        0.03786,
        0.009053,
        0.040329,
        0.20823,
        0.139918,
        0.04856,
        0.095473,
        0.065844,
        0.0,
        0.0,
        0.0,
        0.0,
        0.0,
        0.0,
        0.0,
        0.0,
        0.0,
        0.0,
        0.0,
        0.0
      ],
      "side_imbalance": 0.521541,
      "order_density": 0.133333,
      "source_rows": 400,
      "organism_clock": "2025-04-14T09:23:00.751362-04:00"
    },
    {
      "frame_index": 6,
      "timestamp": "2025-04-14T09:23:01.447195-04:00",
      "life_progress": 0.013483,
      "liquidity_density_factor": 0.422145,
