data/replay_0926.json
{
  "strike_min": 5443.25,
  "strike_max": 5544.5,
  "num_lanes": 24,
  "frames": [
    {
      "frame_index": 0,
      "timestamp": "2025-04-14T09:26:00.132171-04:00",
      "life_progress": 0.0,
      "liquidity_density_factor": 0.146341,
      "gamma_metabolism_factor": 0.258534,
      "manipulation_factor": 0.0,
      "price_kinetic_factor": 0.0,
      "health_score": 0.794391,
      "health_state": "stable",
      "ask_flow": [
        0.0,
        0.0,
        0.0,
        0.0,
        0.0,
        0.0,
        0.0,
        0.0,
        0.0,
        0.0,
        0.0,
        0.0,
        0.858736,
        0.951673,
        0.672862,
        0.306691,
        0.381041,
        0.330855,
        0.436803,
        0.600372,
        0.243494,
        0.223048,
        0.27881,
        0.124535
      ],
      "bid_flow": [
        0.202602,
        0.184015,
        0.009294,
        0.066914,
        0.01487,
        0.070632,
        0.005576,
        0.026022,
        0.815985,
        0.157993,
        0.226766,
        0.135688,
        0.007435,
        0.0,
        0.0,
        0.0,
        0.0,
        0.0,
        0.0,
        0.0,
        0.0,
        0.0,
        0.0,
        0.0
      ],
      "side_imbalance": 0.475285,
      "order_density": 0.5,
      "source_rows": 400,
      "organism_clock": "2025-04-14T09:26:00.132171-04:00"
    },
    {
      "frame_index": 1,
      "timestamp": "2025-04-14T09:26:01.217269-04:00",
      "life_progress": 0.002141,
      "liquidity_density_factor": 0.146341,
      "gamma_metabolism_factor": 0.259436,
      "manipulation_factor": 0.0,
      "price_kinetic_factor": 0.0,
      "health_score": 0.794121,
      "health_state": "stable",
      "ask_flow": [
        0.0,
        0.0,
        0.0,
        0.0,
        0.0,
        0.0,
        0.0,
        0.0,
        0.0,
        0.0,
        0.0,
        0.0,
        0.858736,
        0.951673,
        0.672862,
        0.306691,
        0.381041,
        0.330855,
        0.436803,
        0.600372,
        0.243494,
        0.223048,
        0.27881,
        0.124535
      ],
      "bid_flow": [
        0.202602,
        0.184015,
        0.009294,
        0.066914,
        0.01487,
        0.070632,
        0.005576,
        0.026022,
        0.815985,
        0.157993,
        0.226766,
        0.135688,
        0.007435,
        0.0,
        0.0,
        0.0,
        0.0,
        0.0,
        0.0,
        0.0,
        0.0,
        0.0,
        0.0,
        0.0
      ],
      "side_imbalance": 0.475285,
      "order_density": 0.5,
      "source_rows": 400,
      "organism_clock": "2025-04-14T09:26:00.260217-04:00"
    },
    {
      "frame_index": 2,
      "timestamp": "2025-04-14T09:26:01.233226-04:00",
      "life_progress": 0.004283,
      "liquidity_density_factor": 0.138211,
      "gamma_metabolism_factor": 0.259436,
      "manipulation_factor": 0.000544,
      "price_kinetic_factor": 0.0,
      "health_score": 0.792711,
      "health_state": "stable",
      "ask_flow": [
        0.0,
        0.0,
        0.0,
        0.0,
        0.0,
        0.0,
        0.0,
        0.0,
        0.0,
        0.0,
        0.0,
        0.0,
        0.858736,
        0.951673,
        0.672862,
        0.306691,
        0.381041,
        0.330855,
        0.436803,
        0.600372,
        0.243494,
        0.223048,
        0.27881,
        0.124535
      ],
      "bid_flow": [
        0.202602,
        0.184015,
        0.009294,
        0.066914,
        0.01487,
        0.070632,
        0.005576,
        0.026022,
        0.815985,
        0.157993,
        0.226766,
        0.135688,
        0.005576,
        0.0,
        0.0,
        0.0,
        0.0,
        0.0,
        0.0,
        0.0,
        0.0,
        0.0,
        0.0,
        0.0
      ],
      "side_imbalance": 0.475659,
      "order_density": 0.5,
      "source_rows": 400,
      "organism_clock": "2025-04-14T09:26:00.388322-04:00"
    },
    {
      "frame_index": 3,
      "timestamp": "2025-04-14T09:26:01.256191-04:00",
      "life_progress": 0.006424,
      "liquidity_density_factor": 0.138211,
      "gamma_metabolism_factor": 0.259436,
      "manipulation_factor": 0.007069,
      "price_kinetic_factor": 0.0,
      "health_score": 0.790427,
      "health_state": "stable",
      "ask_flow": [
        0.0,
        0.0,
        0.0,
        0.0,
        0.0,
        0.0,
        0.0,
        0.0,
        0.0,
        0.0,
        0.0,
        0.0,
        0.85316,
        0.951673,
        0.678439,
        0.306691,
        0.381041,
        0.330855,
        0.436803,
        0.600372,
        0.243494,
        0.223048,
        0.27881,
        0.124535
      ],
      "bid_flow": [
        0.202602,
        0.184015,
        0.009294,
        0.066914,
        0.01487,
        0.070632,
        0.005576,
        0.026022,
        0.815985,
        0.152416,
        0.226766,
        0.141264,
        0.005576,
        0.0,
        0.0,
        0.0,
        0.0,
        0.0,
        0.0,
        0.0,
        0.0,
        0.0,
        0.0,
        0.0
      ],
      "side_imbalance": 0.475659,
      "order_density": 0.5,
      "source_rows": 400,
      "organism_clock": "2025-04-14T09:26:00.516368-04:00"
    },
    {
      "frame_index": 4,
      "timestamp": "2025-04-14T09:26:01.272148-04:00",
      "life_progress": 0.008565,
      "liquidity_density_factor": 0.138211,
      "gamma_metabolism_factor": 0.259436,
      "manipulation_factor": 0.007069,
      "price_kinetic_factor": 0.0,
      "health_score": 0.790427,
      "health_state": "stable",
      "ask_flow": [
        0.0,
        0.0,
        0.0,
        0.0,
        0.0,
        0.0,
        0.0,
        0.0,
        0.0,
        0.0,
        0.0,
        0.0,
        0.85316,
        0.951673,
        0.678439,
        0.306691,
        0.381041,
        0.330855,
        0.436803,
        0.600372,
        0.243494,
        0.223048,
        0.27881,
        0.124535
      ],
      "bid_flow": [
        0.202602,
        0.184015,
        0.009294,
        0.066914,
        0.01487,
        0.070632,
        0.005576,
        0.026022,
        0.815985,
        0.152416,
        0.226766,
        0.141264,
        0.005576,
        0.0,
        0.0,
        0.0,
        0.0,
        0.0,
        0.0,
        0.0,
        0.0,
        0.0,
        0.0,
        0.0
      ],
      "side_imbalance": 0.475659,
      "order_density": 0.5,
      "source_rows": 400,
      "organism_clock": "2025-04-14T09:26:00.644413-04:00"
    },
    {
      "frame_index": 5,
      "timestamp": "2025-04-14T09:26:01.289077-04:00",
      "life_progress": 0.010707,
      "liquidity_density_factor": 0.138211,
      "gamma_metabolism_factor": 0.259436,
      "manipulation_factor": 0.007069,
      "price_kinetic_factor": 0.0,
      "health_score": 0.790427,
      "health_state": "stable",
      "ask_flow": [
        0.0,
        0.0,
        0.0,
        0.0,
        0.0,
        0.0,
        0.0,
        0.0,
        0.0,
        0.0,
        0.0,
        0.0,
        0.85316,
        0.951673,
        0.678439,
        0.306691,
        0.381041,
        0.330855,
        0.436803,
        0.600372,
        0.243494,
        0.223048,
        0.27881,
        0.124535
      ],
      "bid_flow": [
        0.202602,
        0.184015,
        0.009294,
        0.066914,
        0.01487,
        0.070632,
        0.005576,
        0.026022,
        0.815985,
        0.152416,
        0.226766,
        0.141264,
        0.005576,
        0.0,
        0.0,
        0.0,
        0.0,
        0.0,
        0.0,
        0.0,
        0.0,
        0.0,
        0.0,
        0.0
      ],
      "side_imbalance": 0.475659,
      "order_density": 0.5,
      "source_rows": 400,
      "organism_clock": "2025-04-14T09:26:00.772519-04:00"
    },
    {
      "frame_index": 6,
      "timestamp": "2025-04-14T09:26:01.307029-04:00",
      "life_progress": 0.012848,
      "liquidity_density_factor": 0.138211,
